---
description: Docs intro
layout: ../../../layouts/MainLayout.astro
---

# 异常

## 概述

**异常**(Exception)是程序错误发生的信号，当 Python 检测到一个**错误**(Error)时，解释器就会指出当前流已经无法继续执行下去，这时候就会产生一个异常。

如果该异常没有被应用程序处理，那么该异常就会被**抛出**，程序的执行也随之终止。

错误分为两大类:

1. 语法上的错误：在程序运行前就应该**立即修正** ；

2. 逻辑上的错误：程序运行时产生的错误，有时不可避免

   比如：字典没有key，非要取key；列表没有索引；变量没有名字等。

错误被检测到就会导致异常，异常由上部分构成：

1. 异常的追踪信息：即异常在哪里发生
2. 异常的类型
3. 异常的信息

例如，在未定义变量`a`的时候执行：

```python
a += 1
'''
File "D:\Doms\Python基础教程\code\异常\demo.py", line 1, in <module>
	a += 1
NameError: name 'a' is not defined
'''
```

异常的追踪信息对应：`File "D:\Doms\Python基础教程\code\异常\demo.py", line 1, in  	a += 1`的内容；

异常的类型对应：`NameError`

异常的信息对应：`name 'a' is not defined`

为了避免程序因为异常而崩溃，在应用程序中应该对可能出现的异常进行处理，从而增强程序的**健壮性**。

## 异常的类型

异常的类型有很多种，这里列举几个常见的异常：

1. `NameError` 名称未定义异常：

   类似上面的例子，若一个变量未定义时就去使用它，就会抛出这个异常。

2. `IndexError` 索引越界异常：

   例如一个列表（或元组等 ）的索引值不在合法范围内，就会抛出这个异常。

3. `KeyError` 键异常

   例如取字典不存在的键对应的值时，会抛出这个异常

4. `TypeError` 类型异常

   例如你定义了一个整型变量，你却把它当作列表一样取索引，就会抛出这个异常。

5. `SyntaxError` 语法错误异常

   当你的程序有语法错误时，会抛出这个异常，如`if`后没加冒号。这个异常多了，你离离职也不远了(ー`´ー)

6. `Exception`异常

   万用异常类型，无论是什么类型的异常，都会被包括在`Exception`中

7.  自定义异常

   由程序员自己定义的异常，定义方式下面会讲

## 异常的处理

以下几种方式可以对异常进行处理：

1. `try...except...`：

   格式：

   ```python
   try:
       可能出现异常的代码
   except 异常1类型名:
       当抛出的异常是异常1时执行的子代码块
   except ....:
       ...
   else:
       程序未发现异常时执行该代码块
   finally:
       最后执行该代码块（无论怎么样都会执行 ）
   ```

   其中，除了`try...except...`的部分不可或缺，其余的地方若无需求可以省略不写。

   例如，同样是`a`未定义，想要捕获`a += 1`这条语句的异常：

   ```python
   try:
       a += 1
   except NameError:
       print("a还没定义")
   ```

   执行后发现，程序并没有报错，而是打印了`except`中的字符串，这说明异常成功被捕获。
   
   若要查看异常的具体内容，而不让程序直接抛出，我们可以在关键字类型名后加上`as`关键字，再加上一个合法变量名。
   
   该变量代表异常内容，为字符串，例如：
   
   ```python
   try:
       a += 1
   except NameError as f:
       print(f)
   ```
   
   打印了字符串`'name 'a' is not defined'`，符合预期。
   
   再举个例子：
   
   ```python
   L = []
   try:
       L[1]
   except IndexError:
       print("代码有问题")
   else:
       print("代码没问题")
   finally:
       print("结束了捕获过程")
   ```
   
   执行后发现，程序打印了`except`中的字符串和`finally`中的字符串，符合预期。
   
   将`L = []`改为`L = [1, 2]`再执行，会发现程序打印了`else`中的字符串和`finally`中的字符串，也符合预期。
   
   若一段程序中可能会有多种类的异常，我们可以对其进行**分支处理**，例如：
   
   ```python
   di = {"name": "DrSHW"}
   try:					# 代码块可能出现 NameError 和 KeyError，分支处理
       di['age']
       a
       print('=========')
   except NameError:
       print("代码有问题")
   except KeyError:
       print("代码有问题")
   else:
       print("代码没问题")
   finally:
       print("结束了捕获过程")
   ```
   
   我们可以发现，只捕获了代码块中第一个出现的错误，即`KeyError`。
   
   捕获之后，程序**不会**继续执行`try`代码块的内容，而是直接跳转到`except`和`finally`代码块。
   
   若一段代码中可能出现多个异常，且处理的方式都相同（如打印错误信息 ），我们可以用元组的方式将其归到一个分支中，例如：
   
   ```python
   di = {"name": "DrSHW"}
   try:									# 将可能的异常合并处理
       a
       di['age']
   except (NameError, KeyError) as f:		# 以元组的方式合并
       print(f)
   else:
       print("代码没问题")
   ```
   
   也可以使用万能捕获`Exception`（不推荐 ）：
   
   ```python
   di = {"name": "DrSHW"}
   L = []
   try:						# 将可能的异常合并处理
       L[1]
       a
       di['age']
   except Exception as f:		# 直接用Exception进行接收
       print(f)
   else:
       print("代码没问题")
   ```

## 自定义异常

我们可以在程序满足一定条件时，使其抛出异常。

自定义异常的定义方式有两种：

1. 通过`raise`抛出，格式为`raise 异常类型(自定义异常信息)`

   例如：若列表`L`中的类型不全为整型，就抛出`TypeError`：

   ```python
   L = [1, 2, 3, 4, '5']
   for i in L:
       if type(i) != int:
           raise TypeError('L中必须都为整型变量')		# 通过raise抛出异常
   ```

   执行后发现程序报错，抛出了`TypeError`的异常，符合预期。

2. 通过`assert`断言，格式为`assert 自定义条件`，若自定义条件不满足，将会抛出类型为`AssertionError`的错误，例如：

   ```python
   L = [1, 2, 3]
   assert len(L) == 5		# 断言L的长度为5，否则报错
   ```

   执行后发现程序报错，也按预期抛出了`AssertionError`的异常。
